**问题背景**
INTERNALERROR> During handling of the above exception, another exception occurred: INTERNALERROR>  INTERNALERROR> Traceback (most recent call last): INTERNALERROR>   File "/Users/fengjincong/.virtualenvs/EprosTest/.venv/lib/python3.9/site-packages/requests/adapters.py", line 486, in send INTERNALERROR>     resp = conn.urlopen( INTERNALERROR>   File "/Users/fengjincong/.virtualenvs/EprosTest/.venv/lib/python3.9/site-packages/urllib3/connectionpool.py", line 799, in urlopen INTERNALERROR>     retries = retries.increment( INTERNALERROR>   File "/Users/fengjincong/.virtualenvs/EprosTest/.venv/lib/python3.9/site-packages/urllib3/util/retry.py", line 550, in increment INTERNALERROR>     raise six.reraise(type(error), error, _stacktrace) INTERNALERROR>   File "/Users/fengjincong/.virtualenvs/EprosTest/.venv/lib/python3.9/site-packages/urllib3/packages/six.py", line 769, in reraise INTERNALERROR>     raise value.with_traceback(tb) INTERNALERROR>   File "/Users/fengjincong/.virtualenvs/EprosTest/.venv/lib/python3.9/site-packages/urllib3/connectionpool.py", line 715, in urlopen INTERNALERROR>     httplib_response = self._make_request( INTERNALERROR>   File "/Users/fengjincong/.virtualenvs/EprosTest/.venv/lib/python3.9/site-packages/urllib3/connectionpool.py", line 467, in _make_request INTERNALERROR>     six.raise_from(e, None) INTERNALERROR>   File "<string>", line 3, in raise_from INTERNALERROR>   File "/Users/fengjincong/.virtualenvs/EprosTest/.venv/lib/python3.9/site-packages/urllib3/connectionpool.py", line 462, in _make_request INTERNALERROR>     httplib_response = conn.getresponse() INTERNALERROR>   File "/Library/Developer/CommandLineTools/Library/Frameworks/Python3.framework/Versions/3.9/lib/python3.9/http/client.py", line 1349, in getresponse INTERNALERROR>     response.begin() INTERNALERROR>   File "/Library/Developer/CommandLineTools/Library/Frameworks/Python3.framework/Versions/3.9/lib/python3.9/http/client.py", line 316, in begin INTERNALERROR>     version, status, reason = self._read_status() INTERNALERROR>   File "/Library/Developer/CommandLineTools/Library/Frameworks/Python3.framework/Versions/3.9/lib/python3.9/http/client.py", line 277, in _read_status INTERNALERROR>     line = str(self.fp.readline(_MAXLINE + 1), "iso-8859-1") INTERNALERROR>   File "/Library/Developer/CommandLineTools/Library/Frameworks/Python3.framework/Versions/3.9/lib/python3.9/socket.py", line 704, in readinto INTERNALERROR>     return self._sock.recv_into(b) INTERNALERROR> urllib3.exceptions.ProtocolError: ('Connection aborted.', ConnectionResetError(54, 'Connection reset by peer'))



这个错误 `urllib3.exceptions.ProtocolError: ('Connection aborted.', ConnectionResetError(54, 'Connection reset by peer'))` 是典型的**网络连接中断问题**，发生在客户端（你的测试脚本）与服务器之间的通信过程中。以下是具体原因分析和排查步骤：


### **一、核心原因：服务器或网络主动中断连接**
错误信息中的 `Connection reset by peer`（对端重置连接）表示**服务器端或网络中间设备（如防火墙、代理）主动关闭了当前连接**，导致客户端无法继续通信。常见触发场景如下：


### **二、具体可能原因及排查**

#### **1. 服务器端主动断开连接**
服务器可能因以下原因主动关闭连接：
- **请求异常**：请求头/体格式错误、缺少必要参数（如认证 Token）、请求体过大（超过服务器限制）。  
  - **排查**：用工具（如 `curl`、Postman）手动发送相同请求，检查服务器返回的状态码（如 400、401、413 等）和响应信息。  
  - **示例**：若请求头缺少 `Authorization`，服务器可能直接断开连接。  

- **服务器超时**：服务器处理请求的时间超过了客户端设置的超时时间，或服务器自身设置了超时（如 Nginx 的 `proxy_read_timeout`）。  
  - **排查**：检查客户端请求的超时设置（`requests` 的 `timeout` 参数），确认是否过短；联系服务器管理员确认服务器端的超时配置。  

- **服务器负载过高**：服务器因高并发或资源不足（CPU/内存耗尽），主动拒绝新连接或断开旧连接。  
  - **排查**：检查服务器的监控指标（如 CPU、内存、连接数），确认是否在测试期间达到瓶颈。  


#### **2. 网络中间设备干扰**
网络中的防火墙、代理、负载均衡器等设备可能因规则限制断开连接：
- **防火墙拦截**：防火墙策略禁止特定 IP、端口或请求内容的通信。  
  - **排查**：检查测试环境的网络策略，确认客户端 IP 是否被允许访问目标服务器；尝试关闭防火墙或添加白名单。  

- **代理配置错误**：若测试脚本通过代理访问服务器，代理服务器可能因配置错误（如过期证书、错误的代理地址）导致连接中断。  
  - **排查**：检查 `requests` 的代理配置（`proxies` 参数），确认代理地址、端口、认证信息是否正确。  

- **DNS 解析失败**：域名解析失败（如 DNS 服务器故障、域名过期）导致客户端无法找到服务器 IP，连接中断。  
  - **排查**：在测试环境中执行 `ping <服务器域名>` 或 `nslookup <服务器域名>`，确认 DNS 解析是否正常。  


#### **3. 客户端请求问题**
客户端（测试脚本）的请求逻辑可能存在缺陷：
- **长连接未正确维护**：若使用 `requests.Session()` 保持长连接（`keep-alive=True`），但服务器不支持或客户端未正确处理重连，可能导致连接被服务器断开后无法恢复。  
  - **排查**：关闭长连接（`Session` 初始化时设置 `trust_env=False` 或 `max_redirects=0`），或在请求中显式禁用 `keep-alive`（添加请求头 `Connection: close`）。  

- **请求频率过高**：短时间内发送大量请求，触发服务器的防刷机制（如速率限制），导致连接被断开。  
  - **排查**：检查测试用例的并发或循环逻辑，添加延迟（`time.sleep()`）或限制请求频率。  


#### **4. 网络不稳定**
物理网络或云环境的网络波动可能导致连接中断：
- **临时网络抖动**：测试环境的网络（如公司内网、云 VPC）可能出现短暂丢包或路由异常。  
  - **排查**：多次重复执行测试用例，观察是否为偶发问题；使用 `ping` 或 `mtr` 工具监控网络延迟和丢包率。  


### **三、针对性解决方法**

#### **1. 验证请求合法性**
- 用工具（如 `curl`）手动发送相同请求，确认服务器是否正常响应：  
  ```bash
  curl -v "https://your-api-endpoint.com" -H "Header-Name: Value" -d "request-body"
  ```
  若手动请求也失败，说明问题在服务器或网络；若手动请求成功，检查测试脚本的请求逻辑（如头信息、参数是否一致）。  


#### **2. 检查超时设置**
- 在 `requests` 请求中显式设置合理的超时时间（避免过短）：  
  ```python
  import requests
  
  response = requests.get(
      "https://your-api-endpoint.com",
      timeout=(3, 10)  # 连接超时3秒，读取超时10秒
  )
  ```


#### **3. 排查网络问题**
- 检查代理配置（若有）：  
  ```python
  proxies = {
      "http": "http://user:pass@proxy:port",
      "https": "https://user:pass@proxy:port"
  }
  response = requests.get("https://your-api-endpoint.com", proxies=proxies)
  ```
- 确认 DNS 解析正常：  
  ```bash
  nslookup your-api-endpoint.com  # 检查域名解析结果
  ```


#### **4. 处理服务器限制**
- 添加重试机制（针对偶发的连接中断）：  
  使用 `urllib3.Retry` 配置重试策略（`requests` 的 `HTTPAdapter` 支持）：  
  ```python
  from requests.adapters import HTTPAdapter
  from urllib3.util.retry import Retry
  
  session = requests.Session()
  retry_strategy = Retry(
      total=3,  # 总重试次数
      backoff_factor=1,  # 重试间隔（秒）
      status_forcelist=[500, 502, 503, 504]  # 针对这些状态码重试
  )
  adapter = HTTPAdapter(max_retries=retry_strategy)
  session.mount("https://", adapter)
  session.mount("http://", adapter)
  
  response = session.get("https://your-api-endpoint.com")
  ```


#### **5. 联系服务器管理员**
- 若手动请求也失败，联系服务器团队检查：  
  - 服务器日志（如 Nginx、Apache、应用日志）是否有对应请求记录。  
  - 服务器是否因负载过高或错误配置（如 `proxy_read_timeout` 过短）断开连接。  


### **四、总结**
该错误的核心是**客户端与服务器的连接被意外中断**，可能由服务器异常、网络问题、客户端请求缺陷等引起。排查步骤建议：  
1. 用工具验证请求合法性 → 2. 检查超时和代理配置 → 3. 排查网络稳定性 → 4. 添加重试机制 → 5. 联系服务器团队。